Workbook

Sheet 🚦 Full Dashboard
B1: 🚦 FULL STRESS TEST DASHBOARD — All 20 Scenarios × 3 Severities
B2: =CONCAT("Base data: ",'Hist_Financials'!B1," | Leverage threshold: ",'Scenario_Setup'!B13,"x | Coverage threshold: ",'Scenario_Setup'!B12,"x | Min cash: ",'Scenario_Setup'!B11)
B4: =COUNTIF('⚙️ Scenario Matrix'!N4:N63,"CRITICAL")&" CRITICAL" | E4: =COUNTIF('⚙️ Scenario Matrix'!N4:N63,"WATCH")&" WATCH" | H4: =COUNTIF('⚙️ Scenario Matrix'!N4:N63,"RESILIENT")&" RESILIENT" | K4: =60&" total scenarios"
B6: BASE CASE REFERENCE → | D6: Revenue ($mm) | E6: EBITDA ($mm) | F6: EBITDA Margin | G6: Net Income | H6: FCF ($mm) | I6: Cash ($mm) | J6: Net Lev. | K6: Int Cov.
D7: ='Hist_Financials'!D6 | E7: ='Hist_Financials'!D11 | F7: =IFERROR('Hist_Financials'!D11/'Hist_Financials'!D6,0) | G7: ='Hist_Financials'!D17 | H7: =IFERROR('Hist_Financials'!D39-'Hist_Financials'!D36,'Hist_Financials'!D17+'Hist_Financials'!D12-'Hist_Financials'!D36) | I7: ='Hist_Financials'!D20 | J7: =IFERROR(('Hist_Financials'!D27+'Hist_Financials'!D30-'Hist_Financials'!D20)/MAX('Hist_Financials'!D11,0.01),0) | K7: =IFERROR('Hist_Financials'!D13/MAX('Hist_Financials'!D14,0.01),0)
B9: SCENARIO / SEVERITY | D9: P&L IMPACT | F9: EARNINGS & CASH GENERATION | I9: CREDIT METRICS | L9: RATING
B10: Scenario | C10: Severity | D10: Revenue Δ | E10: EBITDA Δ | F10: EBITDA Margin % | G10: Net Income | H10: FCF | I10: End Cash | J10: Net Lev. | K10: Int Cov. | L10: ⚡ Outcome
B11: ='⚙️ Scenario Matrix'!B4 | C11: ='⚙️ Scenario Matrix'!C4 | D11: ='⚙️ Scenario Matrix'!E4 | E11: ='⚙️ Scenario Matrix'!H4 | F11: ='⚙️ Scenario Matrix'!F4 | G11: ='⚙️ Scenario Matrix'!I4 | H11: ='⚙️ Scenario Matrix'!J4 | I11: ='⚙️ Scenario Matrix'!K4 | J11: ='⚙️ Scenario Matrix'!L4 | K11: ='⚙️ Scenario Matrix'!M4 | L11: ='⚙️ Scenario Matrix'!N4
B12: ='⚙️ Scenario Matrix'!B5 | C12: ='⚙️ Scenario Matrix'!C5 | D12: ='⚙️ Scenario Matrix'!E5 | E12: ='⚙️ Scenario Matrix'!H5 | F12: ='⚙️ Scenario Matrix'!F5 | G12: ='⚙️ Scenario Matrix'!I5 | H12: ='⚙️ Scenario Matrix'!J5 | I12: ='⚙️ Scenario Matrix'!K5 | J12: ='⚙️ Scenario Matrix'!L5 | K12: ='⚙️ Scenario Matrix'!M5 | L12: ='⚙️ Scenario Matrix'!N5
B13: ='⚙️ Scenario Matrix'!B6 | C13: ='⚙️ Scenario Matrix'!C6 | D13: ='⚙️ Scenario Matrix'!E6 | E13: ='⚙️ Scenario Matrix'!H6 | F13: ='⚙️ Scenario Matrix'!F6 | G13: ='⚙️ Scenario Matrix'!I6 | H13: ='⚙️ Scenario Matrix'!J6 | I13: ='⚙️ Scenario Matrix'!K6 | J13: ='⚙️ Scenario Matrix'!L6 | K13: ='⚙️ Scenario Matrix'!M6 | L13: ='⚙️ Scenario Matrix'!N6
B14: ='⚙️ Scenario Matrix'!B7 | C14: ='⚙️ Scenario Matrix'!C7 | D14: ='⚙️ Scenario Matrix'!E7 | E14: ='⚙️ Scenario Matrix'!H7 | F14: ='⚙️ Scenario Matrix'!F7 | G14: ='⚙️ Scenario Matrix'!I7 | H14: ='⚙️ Scenario Matrix'!J7 | I14: ='⚙️ Scenario Matrix'!K7 | J14: ='⚙️ Scenario Matrix'!L7 | K14: ='⚙️ Scenario Matrix'!M7 | L14: ='⚙️ Scenario Matrix'!N7
B15: ='⚙️ Scenario Matrix'!B8 | C15: ='⚙️ Scenario Matrix'!C8 | D15: ='⚙️ Scenario Matrix'!E8 | E15: ='⚙️ Scenario Matrix'!H8 | F15: ='⚙️ Scenario Matrix'!F8 | G15: ='⚙️ Scenario Matrix'!I8 | H15: ='⚙️ Scenario Matrix'!J8 | I15: ='⚙️ Scenario Matrix'!K8 | J15: ='⚙️ Scenario Matrix'!L8 | K15: ='⚙️ Scenario Matrix'!M8 | L15: ='⚙️ Scenario Matrix'!N8
B16: ='⚙️ Scenario Matrix'!B9 | C16: ='⚙️ Scenario Matrix'!C9 | D16: ='⚙️ Scenario Matrix'!E9 | E16: ='⚙️ Scenario Matrix'!H9 | F16: ='⚙️ Scenario Matrix'!F9 | G16: ='⚙️ Scenario Matrix'!I9 | H16: ='⚙️ Scenario Matrix'!J9 | I16: ='⚙️ Scenario Matrix'!K9 | J16: ='⚙️ Scenario Matrix'!L9 | K16: ='⚙️ Scenario Matrix'!M9 | L16: ='⚙️ Scenario Matrix'!N9
B17: ='⚙️ Scenario Matrix'!B10 | C17: ='⚙️ Scenario Matrix'!C10 | D17: ='⚙️ Scenario Matrix'!E10 | E17: ='⚙️ Scenario Matrix'!H10 | F17: ='⚙️ Scenario Matrix'!F10 | G17: ='⚙️ Scenario Matrix'!I10 | H17: ='⚙️ Scenario Matrix'!J10 | I17: ='⚙️ Scenario Matrix'!K10 | J17: ='⚙️ Scenario Matrix'!L10 | K17: ='⚙️ Scenario Matrix'!M10 | L17: ='⚙️ Scenario Matrix'!N10
B18: ='⚙️ Scenario Matrix'!B11 | C18: ='⚙️ Scenario Matrix'!C11 | D18: ='⚙️ Scenario Matrix'!E11 | E18: ='⚙️ Scenario Matrix'!H11 | F18: ='⚙️ Scenario Matrix'!F11 | G18: ='⚙️ Scenario Matrix'!I11 | H18: ='⚙️ Scenario Matrix'!J11 | I18: ='⚙️ Scenario Matrix'!K11 | J18: ='⚙️ Scenario Matrix'!L11 | K18: ='⚙️ Scenario Matrix'!M11 | L18: ='⚙️ Scenario Matrix'!N11
B19: ='⚙️ Scenario Matrix'!B12 | C19: ='⚙️ Scenario Matrix'!C12 | D19: ='⚙️ Scenario Matrix'!E12 | E19: ='⚙️ Scenario Matrix'!H12 | F19: ='⚙️ Scenario Matrix'!F12 | G19: ='⚙️ Scenario Matrix'!I12 | H19: ='⚙️ Scenario Matrix'!J12 | I19: ='⚙️ Scenario Matrix'!K12 | J19: ='⚙️ Scenario Matrix'!L12 | K19: ='⚙️ Scenario Matrix'!M12 | L19: ='⚙️ Scenario Matrix'!N12
B20: ='⚙️ Scenario Matrix'!B13 | C20: ='⚙️ Scenario Matrix'!C13 | D20: ='⚙️ Scenario Matrix'!E13 | E20: ='⚙️ Scenario Matrix'!H13 | F20: ='⚙️ Scenario Matrix'!F13 | G20: ='⚙️ Scenario Matrix'!I13 | H20: ='⚙️ Scenario Matrix'!J13 | I20: ='⚙️ Scenario Matrix'!K13 | J20: ='⚙️ Scenario Matrix'!L13 | K20: ='⚙️ Scenario Matrix'!M13 | L20: ='⚙️ Scenario Matrix'!N13
B21: ='⚙️ Scenario Matrix'!B14 | C21: ='⚙️ Scenario Matrix'!C14 | D21: ='⚙️ Scenario Matrix'!E14 | E21: ='⚙️ Scenario Matrix'!H14 | F21: ='⚙️ Scenario Matrix'!F14 | G21: ='⚙️ Scenario Matrix'!I14 | H21: ='⚙️ Scenario Matrix'!J14 | I21: ='⚙️ Scenario Matrix'!K14 | J21: ='⚙️ Scenario Matrix'!L14 | K21: ='⚙️ Scenario Matrix'!M14 | L21: ='⚙️ Scenario Matrix'!N14
B22: ='⚙️ Scenario Matrix'!B15 | C22: ='⚙️ Scenario Matrix'!C15 | D22: ='⚙️ Scenario Matrix'!E15 | E22: ='⚙️ Scenario Matrix'!H15 | F22: ='⚙️ Scenario Matrix'!F15 | G22: ='⚙️ Scenario Matrix'!I15 | H22: ='⚙️ Scenario Matrix'!J15 | I22: ='⚙️ Scenario Matrix'!K15 | J22: ='⚙️ Scenario Matrix'!L15 | K22: ='⚙️ Scenario Matrix'!M15 | L22: ='⚙️ Scenario Matrix'!N15
... B70: ='⚙️ Scenario Matrix'!B63 | C70: ='⚙️ Scenario Matrix'!C63 | D70: ='⚙️ Scenario Matrix'!E63 | E70: ='⚙️ Scenario Matrix'!H63 | F70: ='⚙️ Scenario Matrix'!F63 | G70: ='⚙️ Scenario Matrix'!I63 | H70: ='⚙️ Scenario Matrix'!J63 | I70: ='⚙️ Scenario Matrix'!K63 | J70: ='⚙️ Scenario Matrix'!L63 | K70: ='⚙️ Scenario Matrix'!M63 | L70: ='⚙️ Scenario Matrix'!N63
B72: LEGEND: 🔴 CRITICAL = leverage breaches threshold OR coverage < min OR equity < 0 OR FCF < -20% revenue 🟡 WATCH = FCF negative OR leverage 3x–threshold 🟢 RESILIENT = FCF ≥ 0, leverage < 3x, coverage ≥ min, equity positive Delta columns: green = better, red = worse than base
B73: =CONCAT("Active thresholds → Max Net Leverage: ",'Scenario_Setup'!B13,"x | Min EBIT/Interest: ",'Scenario_Setup'!B12,"x | Min Cash Buffer: $",'Scenario_Setup'!B11,"mm — Change these in Scenario_Setup")

Sheet ⚙️ Scenario Matrix
B1: ⚙️ SCENARIO MATRIX ENGINE — All 60 Scenarios × Severities Computed Simultaneously
B2: Calculation engine — all formulas reference Hist_Financials and Scenario_Library directly. Do not edit. Change base data in Hist_Financials, thresholds in Scenario_Setup.
B3: Scenario | C3: Severity | D3: Revenue (Stressed) | E3: Revenue Δ | F3: EBITDA Margin (Stressed) | G3: EBITDA (Stressed) | H3: EBITDA Δ | I3: Net Income (Stressed) | J3: FCF (Stressed) | K3: Ending Cash | L3: Net Leverage | M3: Int Coverage | N3: Rating
B4: ='Scenario_Library'!A7 | C4: Light | D4: ='Hist_Financials'!D6*(1+'Scenario_Library'!E7) | E4: =('Hist_Financials'!D6*(1+'Scenario_Library'!E7))-'Hist_Financials'!D6 | F4: =IFERROR(((('Hist_Financials'!D6*(1+'Scenario_Library'!E7))*(MAX(-0.5,MIN(0.9,IFERROR('Hist_Financials'!D8/'Hist_Financials'!D6,0)+'Scenario_Library'!F7/10000))))-(MAX(0,'Hist_Financials'!D9*(1+'Scenario_Setup'!B9*('Scenario_Library'!E7)+('Scenario_Library'!G7))))-(MAX(0,'Hist_Financials'!D10*(1+'Scenario_Library'!H7))))/('Hist_Financials'!D6*(1+'Scenario_Library'!E7)),0) | G4: =(('Hist_Financials'!D6*(1+'Scenario_Library'!E7))*(MAX(-0.5,MIN(0.9,IFERROR('Hist_Financials'!D8/'Hist_Financials'!D6,0)+'Scenario_Library'!F7/10000))))-(MAX(0,'Hist_Financials'!D9*(1+'Scenario_Setup'!B9*('Scenario_Library'!E7)+('Scenario_Library'!G7))))-(MAX(0,'Hist_Financials'!D10*(1+'Scenario_Library'!H7))) | H4: =((('Hist_Financials'!D6*(1+'Scenario_Library'!E7))*(MAX(-0.5,MIN(0.9,IFERROR('Hist_Financials'!D8/'Hist_Financials'!D6,0)+'Scenario_Library'!F7/10000))))-(MAX(0,'Hist_Financials'!D9*(1+'Scenario_Setup'!B9*('Scenario_Library'!E7)+('Scenario_Library'!G7))))-(MAX(0,'Hist_Financials'!D10*(1+'Scenario_Library'!H7))))-'Hist_Financials'!D11 | I4: =((((('Hist_Financials'!D6*(1+'Scenario_Library'!E7))*(MAX(-0.5,MIN(0.9,IFERROR('Hist_Financials'!D8/'Hist_Financials'!D6,0)+'Scenario_Library'!F7/10000))))-(MAX(0,'Hist_Financials'!D9*(1+'Scenario_Setup'!B9*('Scenario_Library'!E7)+('Scenario_Library'!G7))))-(MAX(0,'Hist_Financials'!D10*(1+'Scenario_Library'!H7))))-'Hist_Financials'!D12)-((MAX(0,IFERROR('Hist_Financials'!D14/MAX('Hist_Financials'!D27+'Hist_Financials'!D30,1),0)+'Scenario_Library'!L7/10000))*('Hist_Financials'!D27+'Hist_Financials'!D30))-('Hist_Financials'!D24*'Scenario_Library'!S7)-('Hist_Financials'!D25*'Scenario_Library'!T7)-('Hist_Financials'!D6*'Scenario_Library'!U7))-(MAX(0,((((('Hist_Financials'!D6*(1+'Scenario_Library'!E7))*(MAX(-0.5,MIN(0.9,IFERROR('Hist_Financials'!D8/'Hist_Financials'!D6,0)+'Scenario_Library'!F7/10000))))-(MAX(0,'Hist_Financials'!D9*(1+'Scenario_Setup'!B9*('Scenario_Library'!E7)+('Scenario_Library'!G7))))-(MAX(0,'Hist_Financials'!D10*(1+'Scenario_Library'!H7))))-'Hist_Financials'!D12)-((MAX(0,IFERROR('Hist_Financials'!D14/MAX('Hist_Financials'!D27+'Hist_Financials'!D30,1),0)+'Scenario_Library'!L7/10000))*('Hist_Financials'!D27+'Hist_Financials'!D30))-('Hist_Financials'!D24*'Scenario_Library'!S7)-('Hist_Financials'!D25*'Scenario_Library'!T7)-('Hist_Financials'!D6*'Scenario_Library'!U7)))*'Scenario_Library'!V7) | J4: =((((((('Hist_Financials'!D6*(1+'Scenario_Library'!E7))*(MAX(-0.5,MIN(0.9,IFERROR('Hist_Financials'!D8/'Hist_Financials'!D6,0)+'Scenario_Library'!F7/10000))))-(MAX(0,'Hist_Financials'!D9*(1+'Scenario_Setup'!B9*('Scenario_Library'!E7)+('Scenario_Library'!G7))))-(MAX(0,'Hist_Financials'!D10*(1+'Scenario_Library'!H7))))-'Hist_Financials'!D12)-((MAX(0,IFERROR('Hist_Financials'!D14/MAX('Hist_Financials'!D27+'Hist_Financials'!D30,1),0)+'Scenario_Library'!L7/10000))*('Hist_Financials'!D27+'Hist_Financials'!D30))-('Hist_Financials'!D24*'Scenario_Library'!S7)-('Hist_Financials'!D25*'Scenario_Library'!T7)-('Hist_Financials'!D6*'Scenario_Library'!U7))-(MAX(0,((((('Hist_Financials'!D6*(1+'Scenario_Library'!E7))*(MAX(-0.5,MIN(0.9,IFERROR('Hist_Financials'!D8/'Hist_Financials'!D6,0)+'Scenario_Library'!F7/10000))))-(MAX(0,'Hist_Financials'!D9*(1+'Scenario_Setup'!B9*('Scenario_Library'!E7)+('Scenario_Library'!G7))))-(MAX(0,'Hist_Financials'!D10*(1+'Scenario_Library'!H7))))-'Hist_Financials'!D12)-((MAX(0,IFERROR('Hist_Financials'!D14/MAX('Hist_Financials'!D27+'Hist_Financials'!D30,1),0)+'Scenario_Library'!L7/10000))*('Hist_Financials'!D27+'Hist_Financials'!D30))-('Hist_Financials'!D24*'Scenario_Library'!S7)-('Hist_Financials'!D25*'Scenario_Library'!T7)-('Hist_Financials'!D6*'Scenario_Library'!U7)))*'Scenario_Library'!V7))+'Hist_Financials'!D12+('Hist_Financials'!D24*'Scenario_Library'!S7)+('Hist_Financials'!D25*'Scenario_Library'!T7)-( (('Hist_Financials'!D6*(1+'Scenario_Library'!E7))*(MAX(0,IFERROR('Hist_Financials'!D21/'Hist_Financials'!D6*365,0)+'Scenario_Library'!I7))/365)-'Hist_Financials'!D21 )-( (IFERROR(('Hist_Financials'!D6*(1+'Scenario_Library'!E7))*(1-(MAX(-0.5,MIN(0.9,IFERROR('Hist_Financials'!D8/'Hist_Financials'!D6,0)+'Scenario_Library'!F7/10000))))*(MAX(0,IFERROR('Hist_Financials'!D22/'Hist_Financials'!D7*365,0)+'Scenario_Library'!J7))/365,0))-'Hist_Financials'!D22 )+( (IFERROR(('Hist_Financials'!D6*(1+'Scenario_Library'!E7))*(1-(MAX(-0.5,MIN(0.9,IFERROR('Hist_Financials'!D8/'Hist_Financials'!D6,0)+'Scenario_Library'!F7/10000))))*(MAX(0,IFERROR('Hist_Financials'!D28/'Hist_Financials'!D7*365,0)+'Scenario_Library'!K7))/365,0))-'Hist_Financials'!D28 ))-('Hist_Financials'!D36*(1-'Scenario_Library'!P7)) | K4: =MAX(0,'Hist_Financials'!D20+((((((('Hist_Financials'!D6*(1+'Scenario_Library'!E7))*(MAX(-0.5,MIN(0.9,IFERROR('Hist_Financials'!D8/'Hist_Financials'!D6,0)+'Scenario_Library'!F7/10000))))-(MAX(0,'Hist_Financials'!D9*(1+'Scenario_Setup'!B9*('Scenario_Library'!E7)+('Scenario_Library'!G7))))-(MAX(0,'Hist_Financials'!D10*(1+'Scenario_Library'!H7))))-'Hist_Financials'!D12)-((MAX(0,IFERROR('Hist_Financials'!D14/MAX('Hist_Financials'!D27+'Hist_Financials'!D30,1),0)+'Scenario_Library'!L7/10000))*('Hist_Financials'!D27+'Hist_Financials'!D30))-('Hist_Financials'!D24*'Scenario_Library'!S7)-('Hist_Financials'!D25*'Scenario_Library'!T7)-('Hist_Financials'!D6*'Scenario_Library'!U7))-(MAX(0,((((('Hist_Financials'!D6*(1+'Scenario_Library'!E7))*(MAX(-0.5,MIN(0.9,IFERROR('Hist_Financials'!D8/'Hist_Financials'!D6,0)+'Scenario_Library'!F7/10000))))-(MAX(0,'Hist_Financials'!D9*(1+'Scenario_Setup'!B9*('Scenario_Library'!E7)+('Scenario_Library'!G7))))-(MAX(0,'Hist_Financials'!D10*(1+'Scenario_Library'!H7))))-'Hist_Financials'!D12)-((MAX(0,IFERROR('Hist_Financials'!D14/MAX('Hist_Financials'!D27+'Hist_Financials'!D30,1),0)+'Scenario_Library'!L7/10000))*('Hist_Financials'!D27+'Hist_Financials'!D30))-('Hist_Financials'!D24*'Scenario_Library'!S7)-('Hist_Financials'!D25*'Scenario_Library'!T7)-('Hist_Financials'!D6*'Scenario_Library'!U7)))*'Scenario_Library'!V7))+'Hist_Financials'!D12+('Hist_Financials'!D24*'Scenario_Library'!S7)+('Hist_Financials'!D25*'Scenario_Library'!T7)-( (('Hist_Financials'!D6*(1+'Scenario_Library'!E7))*(MAX(0,IFERROR('Hist_Financials'!D21/'Hist_Financials'!D6*365,0)+'Scenario_Library'!I7))/365)-'Hist_Financials'!D21 )-( (IFERROR(('Hist_Financials'!D6*(1+'Scenario_Library'!E7))*(1-(MAX(-0.5,MIN(0.9,IFERROR('Hist_Financials'!D8/'Hist_Financials'!D6,0)+'Scenario_Library'!F7/10000))))*(MAX(0,IFERROR('Hist_Financials'!D22/'Hist_Financials'!D7*365,0)+'Scenario_Library'!J7))/365,0))-'Hist_Financials'!D22 )+( (IFERROR(('Hist_Financials'!D6*(1+'Scenario_Library'!E7))*(1-(MAX(-0.5,MIN(0.9,IFERROR('Hist_Financials'!D8/'Hist_Financials'!D6,0)+'Scenario_Library'!F7/10000))))*(MAX(0,IFERROR('Hist_Financials'!D28/'Hist_Financials'!D7*365,0)+'Scenario_Library'!K7))/365,0))-'Hist_Financials'!D28 ))-('Hist_Financials'!D36*(1-'Scenario_Library'!P7))-('Hist_Financials'!D37*(1-'Scenario_Library'!Q7))-('Hist_Financials'!D38*(1-'Scenario_Library'!R7))-('Hist_Financials'!D27*(1-'Scenario_Library'!M7))-('Hist_Financials'!D30*'Scenario_Library'!N7*(1-'Scenario_Library'!O7))) | L4: =IF('Hist_Financials'!D6=0,"",IFERROR(( (('Hist_Financials'!D27-('Hist_Financials'!D27*(1-'Scenario_Library'!M7)))+('Hist_Financials'!D30-('Hist_Financials'!D30*'Scenario_Library'!N7*(1-'Scenario_Library'!O7))))-(MAX(0,'Hist_Financials'!D20+((((((('Hist_Financials'!D6*(1+'Scenario_Library'!E7))*(MAX(-0.5,MIN(0.9,IFERROR('Hist_Financials'!D8/'Hist_Financials'!D6,0)+'Scenario_Library'!F7/10000))))-(MAX(0,'Hist_Financials'!D9*(1+'Scenario_Setup'!B9*('Scenario_Library'!E7)+('Scenario_Library'!G7))))-(MAX(0,'Hist_Financials'!D10*(1+'Scenario_Library'!H7))))-'Hist_Financials'!D12)-((MAX(0,IFERROR('Hist_Financials'!D14/MAX('Hist_Financials'!D27+'Hist_Financials'!D30,1),0)+'Scenario_Library'!L7/10000))*('Hist_Financials'!D27+'Hist_Financials'!D30))-('Hist_Financials'!D24*'Scenario_Library'!S7)-('Hist_Financials'!D25*'Scenario_Library'!T7)-('Hist_Financials'!D6*'Scenario_Library'!U7))-(MAX(0,((((('Hist_Financials'!D6*(1+'Scenario_Library'!E7))*(MAX(-0.5,MIN(0.9,IFERROR('Hist_Financials'!D8/'Hist_Financials'!D6,0)+'Scenario_Library'!F7/10000))))-(MAX(0,'Hist_Financials'!D9*(1+'Scenario_Setup'!B9*('Scenario_Library'!E7)+('Scenario_Library'!G7))))-(MAX(0,'Hist_Financials'!D10*(1+'Scenario_Library'!H7))))-'Hist_Financials'!D12)-((MAX(0,IFERROR('Hist_Financials'!D14/MAX('Hist_Financials'!D27+'Hist_Financials'!D30,1),0)+'Scenario_Library'!L7/10000))*('Hist_Financials'!D27+'Hist_Financials'!D30))-('Hist_Financials'!D24*'Scenario_Library'!S7)-('Hist_Financials'!D25*'Scenario_Library'!T7)-('Hist_Financials'!D6*'Scenario_Library'!U7)))*'Scenario_Library'!V7))+'Hist_Financials'!D12+('Hist_Financials'!D24*'Scenario_Library'!S7)+('Hist_Financials'!D25*'Scenario_Library'!T7)-( (('Hist_Financials'!D6*(1+'Scenario_Library'!E7))*(MAX(0,IFERROR('Hist_Financials'!D21/'Hist_Financials'!D6*365,0)+'Scenario_Library'!I7))/365)-'Hist_Financials'!D21 )-( (IFERROR(('Hist_Financials'!D6*(1+'Scenario_Library'!E7))*(1-(MAX(-0.5,MIN(0.9,IFERROR('Hist_Financials'!D8/'Hist_Financials'!D6,0)+'Scenario_Library'!F7/10000))))*(MAX(0,IFERROR('Hist_Financials'!D22/'Hist_Financials'!D7*365,0)+'Scenario_Library'!J7))/365,0))-'Hist_Financials'!D22 )+( (IFERROR(('Hist_Financials'!D6*(1+'Scenario_Library'!E7))*(1-(MAX(-0.5,MIN(0.9,IFERROR('Hist_Financials'!D8/'Hist_Financials'!D6,0)+'Scenario_Library'!F7/10000))))*(MAX(0,IFERROR('Hist_Financials'!D28/'Hist_Financials'!D7*365,0)+'Scenario_Library'!K7))/365,0))-'Hist_Financials'!D28 ))-('Hist_Financials'!D36*(1-'Scenario_Library'!P7))-('Hist_Financials'!D37*(1-'Scenario_Library'!Q7))-('Hist_Financials'!D38*(1-'Scenario_Library'!R7))-('Hist_Financials'!D27*(1-'Scenario_Library'!M7))-('Hist_Financials'!D30*'Scenario_Library'!N7*(1-'Scenario_Library'!O7)))) )/MAX(((('Hist_Financials'!D6*(1+'Scenario_Library'!E7))*(MAX(-0.5,MIN(0.9,IFERROR('Hist_Financials'!D8/'Hist_Financials'!D6,0)+'Scenario_Library'!F7/10000))))-(MAX(0,'Hist_Financials'!D9*(1+'Scenario_Setup'!B9*('Scenario_Library'!E7)+('Scenario_Library'!G7))))-(MAX(0,'Hist_Financials'!D10*(1+'Scenario_Library'!H7)))),0.01),99)) | M4: =IF('Hist_Financials'!D6=0,"",IFERROR((((('Hist_Financials'!D6*(1+'Scenario_Library'!E7))*(MAX(-0.5,MIN(0.9,IFERROR('Hist_Financials'!D8/'Hist_Financials'!D6,0)+'Scenario_Library'!F7/10000))))-(MAX(0,'Hist_Financials'!D9*(1+'Scenario_Setup'!B9*('Scenario_Library'!E7)+('Scenario_Library'!G7))))-(MAX(0,'Hist_Financials'!D10*(1+'Scenario_Library'!H7))))-'Hist_Financials'!D12)/MAX(((MAX(0,IFERROR('Hist_Financials'!D14/MAX('Hist_Financials'!D27+'Hist_Financials'!D30,1),0)+'Scenario_Library'!L7/10000))*('Hist_Financials'!D27+'Hist_Financials'!D30)),0.01),999)) | N4: =IF('Hist_Financials'!D6=0,"— NO DATA —",IF(OR((IFERROR(( (('Hist_Financials'!D27-('Hist_Financials'!D27*(1-'Scenario_Library'!M7)))+('Hist_Financials'!D30-('Hist_Financials'!D30*'Scenario_Library'!N7*(1-'Scenario_Library'!O7))))-(MAX(0,'Hist_Financials'!D20+((((((('Hist_Financials'!D6*(1+'Scenario_Library'!E7))*(MAX(-0.5,MIN(0.9,IFERROR('Hist_Financials'!D8/'Hist_Financials'!D6,0)+'Scenario_Library'!F7/10000))))-(MAX(0,'Hist_Financials'!D9*(1+'Scenario_Setup'!B9*('Scenario_Library'!E7)+('Scenario_Library'!G7))))-(MAX(0,'Hist_Financials'!D10*(1+'Scenario_Library'!H7))))-'Hist_Financials'!D12)-((MAX(0,IFERROR('Hist_Financials'!D14/MAX('Hist_Financials'!D27+'Hist_Financials'!D30,1),0)+'Scenario_Library'!L7/10000))*('Hist_Financials'!D27+'Hist_Financials'!D30))-('Hist_Financials'!D24*'Scenario_Library'!S7)-('Hist_Financials'!D25*'Scenario_Library'!T7)-('Hist_Financials'!D6*'Scenario_Library'!U7))-(MAX(0,((((('Hist_Financials'!D6*(1+'Scenario_Library'!E7))*(MAX(-0.5,MIN(0.9,IFERROR('Hist_Financials'!D8/'Hist_Financials'!D6,0)+'Scenario_Library'!F7/10000))))-(MAX(0,'Hist_Financials'!D9*(1+'Scenario_Setup'!B9*('Scenario_Library'!E7)+('Scenario_Library'!G7))))-(MAX(0,'Hist_Financials'!D10*(1+'Scenario_Library'!H7))))-'Hist_Financials'!D12)-((MAX(0,IFERROR('Hist_Financials'!D14/MAX('Hist_Financials'!D27+'Hist_Financials'!D30,1),0)+'Scenario_Library'!L7/10000))*('Hist_Financials'!D27+'Hist_Financials'!D30))-('Hist_Financials'!D24*'Scenario_Library'!S7)-('Hist_Financials'!D25*'Scenario_Library'!T7)-('Hist_Financials'!D6*'Scenario_Library'!U7)))*'Scenario_Library'!V7))+'Hist_Financials'!D12+('Hist_Financials'!D24*'Scenario_Library'!S7)+('Hist_Financials'!D25*'Scenario_Library'!T7)-( (('Hist_Financials'!D6*(1+'Scenario_Library'!E7))*(MAX(0,IFERROR('Hist_Financials'!D21/'Hist_Financials'!D6*365,0)+'Scenario_Library'!I7))/365)-'Hist_Financials'!D21 )-( (IFERROR(('Hist_Financials'!D6*(1+'Scenario_Library'!E7))*(1-(MAX(-0.5,MIN(0.9,IFERROR('Hist_Financials'!D8/'Hist_Financials'!D6,0)+'Scenario_Library'!F7/10000))))*(MAX(0,IFERROR('Hist_Financials'!D22/'Hist_Financials'!D7*365,0)+'Scenario_Library'!J7))/365,0))-'Hist_Financials'!D22 )+( (IFERROR(('Hist_Financials'!D6*(1+'Scenario_Library'!E7))*(1-(MAX(-0.5,MIN(0.9,IFERROR('Hist_Financials'!D8/'Hist_Financials'!D6,0)+'Scenario_Library'!F7/10000))))*(MAX(0,IFERROR('Hist_Financials'!D28/'Hist_Financials'!D7*365,0)+'Scenario_Library'!K7))/365,0))-'Hist_Financials'!D28 ))-('Hist_Financials'!D36*(1-'Scenario_Library'!P7))-('Hist_Financials'!D37*(1-'Scenario_Library'!Q7))-('Hist_Financials'!D38*(1-'Scenario_Library'!R7))-('Hist_Financials'!D27*(1-'Scenario_Library'!M7))-('Hist_Financials'!D30*'Scenario_Library'!N7*(1-'Scenario_Library'!O7)))) )/MAX(((('Hist_Financials'!D6*(1+'Scenario_Library'!E7))*(MAX(-0.5,MIN(0.9,IFERROR('Hist_Financials'!D8/'Hist_Financials'!D6,0)+'Scenario_Library'!F7/10000))))-(MAX(0,'Hist_Financials'!D9*(1+'Scenario_Setup'!B9*('Scenario_Library'!E7)+('Scenario_Library'!G7))))-(MAX(0,'Hist_Financials'!D10*(1+'Scenario_Library'!H7)))),0.01),99))>'Scenario_Setup'!B13,(IFERROR((((('Hist_Financials'!D6*(1+'Scenario_Library'!E7))*(MAX(-0.5,MIN(0.9,IFERROR('Hist_Financials'!D8/'Hist_Financials'!D6,0)+'Scenario_Library'!F7/10000))))-(MAX(0,'Hist_Financials'!D9*(1+'Scenario_Setup'!B9*('Scenario_Library'!E7)+('Scenario_Library'!G7))))-(MAX(0,'Hist_Financials'!D10*(1+'Scenario_Library'!H7))))-'Hist_Financials'!D12)/MAX(((MAX(0,IFERROR('Hist_Financials'!D14/MAX('Hist_Financials'!D27+'Hist_Financials'!D30,1),0)+'Scenario_Library'!L7/10000))*('Hist_Financials'!D27+'Hist_Financials'!D30)),0.01),999))<'Scenario_Setup'!B12,('Hist_Financials'!D32+(((((('Hist_Financials'!D6*(1+'Scenario_Library'!E7))*(MAX(-0.5,MIN(0.9,IFERROR('Hist_Financials'!D8/'Hist_Financials'!D6,0)+'Scenario_Library'!F7/10000))))-(MAX(0,'Hist_Financials'!D9*(1+'Scenario_Setup'!B9*('Scenario_Library'!E7)+('Scenario_Library'!G7))))-(MAX(0,'Hist_Financials'!D10*(1+'Scenario_Library'!H7))))-'Hist_Financials'!D12)-((MAX(0,IFERROR('Hist_Financials'!D14/MAX('Hist_Financials'!D27+'Hist_Financials'!D30,1),0)+'Scenario_Library'!L7/10000))*('Hist_Financials'!D27+'Hist_Financials'!D30))-('Hist_Financials'!D24*'Scenario_Library'!S7)-('Hist_Financials'!D25*'Scenario_Library'!T7)-('Hist_Financials'!D6*'Scenario_Library'!U7))-(MAX(0,((((('Hist_Financials'!D6*(1+'Scenario_Library'!E7))*(MAX(-0.5,MIN(0.9,IFERROR('Hist_Financials'!D8/'Hist_Financials'!D6,0)+'Scenario_Library'!F7/10000))))-(MAX(0,'Hist_Financials'!D9*(1+'Scenario_Setup'!B9*('Scenario_Library'!E7)+('Scenario_Library'!G7))))-(MAX(0,'Hist_Financials'!D10*(1+'Scenario_Library'!H7))))-'Hist_Financials'!D12)-((MAX(0,IFERROR('Hist_Financials'!D14/MAX('Hist_Financials'!D27+'Hist_Financials'!D30,1),0)+'Scenario_Library'!L7/10000))*('Hist_Financials'!D27+'Hist_Financials'!D30))-('Hist_Financials'!D24*'Scenario_Library'!S7)-('Hist_Financials'!D25*'Scenario_Library'!T7)-('Hist_Financials'!D6*'Scenario_Library'!U7)))*'Scenario_Library'!V7))-('Hist_Financials'!D37*(1-'Scenario_Library'!Q7))-('Hist_Financials'!D38*(1-'Scenario_Library'!R7)))<0,(((((((('Hist_Financials'!D6*(1+'Scenario_Library'!E7))*(MAX(-0.5,MIN(0.9,IFERROR('Hist_Financials'!D8/'Hist_Financials'!D6,0)+'Scenario_Library'!F7/10000))))-(MAX(0,'Hist_Financials'!D9*(1+'Scenario_Setup'!B9*('Scenario_Library'!E7)+('Scenario_Library'!G7))))-(MAX(0,'Hist_Financials'!D10*(1+'Scenario_Library'!H7))))-'Hist_Financials'!D12)-((MAX(0,IFERROR('Hist_Financials'!D14/MAX('Hist_Financials'!D27+'Hist_Financials'!D30,1),0)+'Scenario_Library'!L7/10000))*('Hist_Financials'!D27+'Hist_Financials'!D30))-('Hist_Financials'!D24*'Scenario_Library'!S7)-('Hist_Financials'!D25*'Scenario_Library'!T7)-('Hist_Financials'!D6*'Scenario_Library'!U7))-(MAX(0,((((('Hist_Financials'!D6*(1+'Scenario_Library'!E7))*(MAX(-0.5,MIN(0.9,IFERROR('Hist_Financials'!D8/'Hist_Financials'!D6,0)+'Scenario_Library'!F7/10000))))-(MAX(0,'Hist_Financials'!D9*(1+'Scenario_Setup'!B9*('Scenario_Library'!E7)+('Scenario_Library'!G7))))-(MAX(0,'Hist_Financials'!D10*(1+'Scenario_Library'!H7))))-'Hist_Financials'!D12)-((MAX(0,IFERROR('Hist_Financials'!D14/MAX('Hist_Financials'!D27+'Hist_Financials'!D30,1),0)+'Scenario_Library'!L7/10000))*('Hist_Financials'!D27+'Hist_Financials'!D30))-('Hist_Financials'!D24*'Scenario_Library'!S7)-('Hist_Financials'!D25*'Scenario_Library'!T7)-('Hist_Financials'!D6*'Scenario_Library'!U7)))*'Scenario_Library'!V7))+'Hist_Financials'!D12+('Hist_Financials'!D24*'Scenario_Library'!S7)+('Hist_Financials'!D25*'Scenario_Library'!T7)-( (('Hist_Financials'!D6*(1+'Scenario_Library'!E7))*(MAX(0,IFERROR('Hist_Financials'!D21/'Hist_Financials'!D6*365,0)+'Scenario_Library'!I7))/365)-'Hist_Financials'!D21 )-( (IFERROR(('Hist_Financials'!D6*(1+'Scenario_Library'!E7))*(1-(MAX(-0.5,MIN(0.9,IFERROR('Hist_Financials'!D8/'Hist_Financials'!D6,0)+'Scenario_Library'!F7/10000))))*(MAX(0,IFERROR('Hist_Financials'!D22/'Hist_Financials'!D7*365,0)+'Scenario_Library'!J7))/365,0))-'Hist_Financials'!D22 )+( (IFERROR(('Hist_Financials'!D6*(1+'Scenario_Library'!E7))*(1-(MAX(-0.5,MIN(0.9,IFERROR('Hist_Financials'!D8/'Hist_Financials'!D6,0)+'Scenario_Library'!F7/10000))))*(MAX(0,IFERROR('Hist_Financials'!D28/'Hist_Financials'!D7*365,0)+'Scenario_Library'!K7))/365,0))-'Hist_Financials'!D28 ))-('Hist_Financials'!D36*(1-'Scenario_Library'!P7)))<-0.2*'Hist_Financials'!D6),"CRITICAL",IF(AND((((((((('Hist_Financials'!D6*(1+'Scenario_Library'!E7))*(MAX(-0.5,MIN(0.9,IFERROR('Hist_Financials'!D8/'Hist_Financials'!D6,0)+'Scenario_Library'!F7/10000))))-(MAX(0,'Hist_Financials'!D9*(1+'Scenario_Setup'!B9*('Scenario_Library'!E7)+('Scenario_Library'!G7))))-(MAX(0,'Hist_Financials'!D10*(1+'Scenario_Library'!H7))))-'Hist_Financials'!D12)-((MAX(0,IFERROR('Hist_Financials'!D14/MAX('Hist_Financials'!D27+'Hist_Financials'!D30,1),0)+'Scenario_Library'!L7/10000))*('Hist_Financials'!D27+'Hist_Financials'!D30))-('Hist_Financials'!D24*'Scenario_Library'!S7)-('Hist_Financials'!D25*'Scenario_Library'!T7)-('Hist_Financials'!D6*'Scenario_Library'!U7))-(MAX(0,((((('Hist_Financials'!D6*(1+'Scenario_Library'!E7))*(MAX(-0.5,MIN(0.9,IFERROR('Hist_Financials'!D8/'Hist_Financials'!D6,0)+'Scenario_Library'!F7/10000))))-(MAX(0,'Hist_Financials'!D9*(1+'Scenario_Setup'!B9*('Scenario_Library'!E7)+('Scenario_Library'!G7))))-(MAX(0,'Hist_Financials'!D10*(1+'Scenario_Library'!H7))))-'Hist_Financials'!D12)-((MAX(0,IFERROR('Hist_Financials'!D14/MAX('Hist_Financials'!D27+'Hist_Financials'!D30,1),0)+'Scenario_Library'!L7/10000))*('Hist_Financials'!D27+'Hist_Financials'!D30))-('Hist_Financials'!D24*'Scenario_Library'!S7)-('Hist_Financials'!D25*'Scenario_Library'!T7)-('Hist_Financials'!D6*'Scenario_Library'!U7)))*'Scenario_Library'!V7))+'Hist_Financials'!D12+('Hist_Financials'!D24*'Scenario_Library'!S7)+('Hist_Financials'!D25*'Scenario_Library'!T7)-( (('Hist_Financials'!D6*(1+'Scenario_Library'!E7))*(MAX(0,IFERROR('Hist_Financials'!D21/'Hist_Financials'!D6*365,0)+'Scenario_Library'!I7))/365)-'Hist_Financials'!D21 )-( (IFERROR(('Hist_Financials'!D6*(1+'Scenario_Library'!E7))*(1-(MAX(-0.5,MIN(0.9,IFERROR('Hist_Financials'!D8/'Hist_Financials'!D6,0)+'Scenario_Library'!F7/10000))))*(MAX(0,IFERROR('Hist_Financials'!D22/'Hist_Financials'!D7*365,0)+'Scenario_Library'!J7))/365,0))-'Hist_Financials'!D22 )+( (IFERROR(('Hist_Financials'!D6*(1+'Scenario_Library'!E7))*(1-(MAX(-0.5,MIN(0.9,IFERROR('Hist_Financials'!D8/'Hist_Financials'!D6,0)+'Scenario_Library'!F7/10000))))*(MAX(0,IFERROR('Hist_Financials'!D28/'Hist_Financials'!D7*365,0)+'Scenario_Library'!K7))/365,0))-'Hist_Financials'!D28 ))-('Hist_Financials'!D36*(1-'Scenario_Library'!P7)))>=0,(IFERROR(( (('Hist_Financials'!D27-('Hist_Financials'!D27*(1-'Scenario_Library'!M7)))+('Hist_Financials'!D30-('Hist_Financials'!D30*'Scenario_Library'!N7*(1-'Scenario_Library'!O7))))-(MAX(0,'Hist_Financials'!D20+((((((('Hist_Financials'!D6*(1+'Scenario_Library'!E7))*(MAX(-0.5,MIN(0.9,IFERROR('Hist_Financials'!D8/'Hist_Financials'!D6,0)+'Scenario_Library'!F7/10000))))-(MAX(0,'Hist_Financials'!D9*(1+'Scenario_Setup'!B9*('Scenario_Library'!E7)+('Scenario_Library'!G7))))-(MAX(0,'Hist_Financials'!D10*(1+'Scenario_Library'!H7))))-'Hist_Financials'!D12)-((MAX(0,IFERROR('Hist_Financials'!D14/MAX('Hist_Financials'!D27+'Hist_Financials'!D30,1),0)+'Scenario_Library'!L7/10000))*('Hist_Financials'!D27+'Hist_Financials'!D30))-('Hist_Financials'!D24*'Scenario_Library'!S7)-('Hist_Financials'!D25*'Scenario_Library'!T7)-('Hist_Financials'!D6*'Scenario_Library'!U7))-(MAX(0,((((('Hist_Financials'!D6*(1+'Scenario_Library'!E7))*(MAX(-0.5,MIN(0.9,IFERROR('Hist_Financials'!D8/'Hist_Financials'!D6,0)+'Scenario_Library'!F7/10000))))-(MAX(0,'Hist_Financials'!D9*(1+'Scenario_Setup'!B9*('Scenario_Library'!E7)+('Scenario_Library'!G7))))-(MAX(0,'Hist_Financials'!D10*(1+'Scenario_Library'!H7))))-'Hist_Financials'!D12)-((MAX(0,IFERROR('Hist_Financials'!D14/MAX('Hist_Financials'!D27+'Hist_Financials'!D30,1),0)+'Scenario_Library'!L7/10000))*('Hist_Financials'!D27+'Hist_Financials'!D30))-('Hist_Financials'!D24*'Scenario_Library'!S7)-('Hist_Financials'!D25*'Scenario_Library'!T7)-('Hist_Financials'!D6*'Scenario_Library'!U7)))*'Scenario_Library'!V7))+'Hist_Financials'!D12+('Hist_Financials'!D24*'Scenario_Library'!S7)+('Hist_Financials'!D25*'Scenario_Library'!T7)-( (('Hist_Financials'!D6*(1+'Scenario_Library'!E7))*(MAX(0,IFERROR('Hist_Financials'!D21/'Hist_Financials'!D6*365,0)+'Scenario_Library'!I7))/365)-'Hist_Financials'!D21 )-( (IFERROR(('Hist_Financials'!D6*(1+'Scenario_Library'!E7))*(1-(MAX(-0.5,MIN(0.9,IFERROR('Hist_Financials'!D8/'Hist_Financials'!D6,0)+'Scenario_Library'!F7/10000))))*(MAX(0,IFERROR('Hist_Financials'!D22/'Hist_Financials'!D7*365,0)+'Scenario_Library'!J7))/365,0))-'Hist_Financials'!D22 )+( (IFERROR(('Hist_Financials'!D6*(1+'Scenario_Library'!E7))*(1-(MAX(-0.5,MIN(0.9,IFERROR('Hist_Financials'!D8/'Hist_Financials'!D6,0)+'Scenario_Library'!F7/10000))))*(MAX(0,IFERROR('Hist_Financials'!D28/'Hist_Financials'!D7*365,0)+'Scenario_Library'!K7))/365,0))-'Hist_Financials'!D28 ))-('Hist_Financials'!D36*(1-'Scenario_Library'!P7))-('Hist_Financials'!D37*(1-'Scenario_Library'!Q7))-('Hist_Financials'!D38*(1-'Scenario_Library'!R7))-('Hist_Financials'!D27*(1-'Scenario_Library'!M7))-('Hist_Financials'!D30*'Scenario_Library'!N7*(1-'Scenario_Library'!O7)))) )/MAX(((('Hist_Financials'!D6*(1+'Scenario_Library'!E7))*(MAX(-0.5,MIN(0.9,IFERROR('Hist_Financials'!D8/'Hist_Financials'!D6,0)+'Scenario_Library'!F7/10000))))-(MAX(0,'Hist_Financials'!D9*(1+'Scenario_Setup'!B9*('Scenario_Library'!E7)+('Scenario_Library'!G7))))-(MAX(0,'Hist_Financials'!D10*(1+'Scenario_Library'!H7)))),0.01),99))<3,(IFERROR((((('Hist_Financials'!D6*(1+'Scenario_Library'!E7))*(MAX(-0.5,MIN(0.9,IFERROR('Hist_Financials'!D8/'Hist_Financials'!D6,0)+'Scenario_Library'!F7/10000))))-(MAX(0,'Hist_Financials'!D9*(1+'Scenario_Setup'!B9*('Scenario_Library'!E7)+('Scenario_Library'!G7))))-(MAX(0,'Hist_Financials'!D10*(1+'Scenario_Library'!H7))))-'Hist_Financials'!D12)/MAX(((MAX(0,IFERROR('Hist_Financials'!D14/MAX('Hist_Financials'!D27+'Hist_Financials'!D30,1),0)+'Scenario_Library'!L7/10000))*('Hist_Financials'!D27+'Hist_Financials'!D30)),0.01),999))>='Scenario_Setup'!B12,('Hist_Financials'!D32+(((((('Hist_Financials'!D6*(1+'Scenario_Library'!E7))*(MAX(-0.5,MIN(0.9,IFERROR('Hist_Financials'!D8/'Hist_Financials'!D6,0)+'Scenario_Library'!F7/10000))))-(MAX(0,'Hist_Financials'!D9*(1+'Scenario_Setup'!B9*('Scenario_Library'!E7)+('Scenario_Library'!G7))))-(MAX(0,'Hist_Financials'!D10*(1+'Scenario_Library'!H7))))-'Hist_Financials'!D12)-((MAX(0,IFERROR('Hist_Financials'!D14/MAX('Hist_Financials'!D27+'Hist_Financials'!D30,1),0)+'Scenario_Library'!L7/10000))*('Hist_Financials'!D27+'Hist_Financials'!D30))-('Hist_Financials'!D24*'Scenario_Library'!S7)-('Hist_Financials'!D25*'Scenario_Library'!T7)-('Hist_Financials'!D6*'Scenario_Library'!U7))-(MAX(0,((((('Hist_Financials'!D6*(1+'Scenario_Library'!E7))*(MAX(-0.5,MIN(0.9,IFERROR('Hist_Financials'!D8/'Hist_Financials'!D6,0)+'Scenario_Library'!F7/10000))))-(MAX(0,'Hist_Financials'!D9*(1+'Scenario_Setup'!B9*('Scenario_Library'!E7)+('Scenario_Library'!G7))))-(MAX(0,'Hist_Financials'!D10*(1+'Scenario_Library'!H7))))-'Hist_Financials'!D12)-((MAX(0,IFERROR('Hist_Financials'!D14/MAX('Hist_Financials'!D27+'Hist_Financials'!D30,1),0)+'Scenario_Library'!L7/10000))*('Hist_Financials'!D27+'Hist_Financials'!D30))-('Hist_Financials'!D24*'Scenario_Library'!S7)-('Hist_Financials'!D25*'Scenario_Library'!T7)-('Hist_Financials'!D6*'Scenario_Library'!U7)))*'Scenario_Library'!V7))-('Hist_Financials'!D37*(1-'Scenario_Library'!Q7))-('Hist_Financials'!D38*(1-'Scenario_Library'!R7)))>0),"RESILIENT","WATCH")))
B5: ='Scenario_Library'!A8 | C5: Base | D5: ='Hist_Financials'!D6*(1+'Scenario_Library'!E8) | E5: =('Hist_Financials'!D6*(1+'Scenario_Library'!E8))-'Hist_Financials'!D6 | F5: =IFERROR(((('Hist_Financials'!D6*(1+'Scenario_Library'!E8))*(MAX(-0.5,MIN(0.9,IFERROR('Hist_Financials'!D8/'Hist_Financials'!D6,0)+'Scenario_Library'!F8/10000))))-(MAX(0,'Hist_Financials'!D9*(1+'Scenario_Setup'!B9*('Scenario_Library'!E8)+('Scenario_Library'!G8))))-(MAX(0,'Hist_Financials'!D10*(1+'Scenario_Library'!H8))))/('Hist_Financials'!D6*(1+'Scenario_Library'!E8)),0) | G5: =(('Hist_Financials'!D6*(1+'Scenario_Library'!E8))*(MAX(-0.5,MIN(0.9,IFERROR('Hist_Financials'!D8/'Hist_Financials'!D6,0)+'Scenario_Library'!F8/10000))))-(MAX(0,'Hist_Financials'!D9*(1+'Scenario_Setup'!B9*('Scenario_Library'!E8)+('Scenario_Library'!G8))))-(MAX(0,'Hist_Financials'!D10*(1+'Scenario_Library'!H8))) | H5: =((('Hist_Financials'!D6*(1+'Scenario_Library'!E8))*(MAX(-0.5,MIN(0.9,IFERROR('Hist_Financials'!D8/'Hist_Financials'!D6,0)+'Scenario_Library'!F8/10000))))-(MAX(0,'Hist_Financials'!D9*(1+'Scenario_Setup'!B9*('Scenario_Library'!E8)+('Scenario_Library'!G8))))-(MAX(0,'Hist_Financials'!D10*(1+'Scenario_Library'!H8))))-'Hist_Financials'!D11 | I5: =((((('Hist_Financials'!D6*(1+'Scenario_Library'!E8))*(MAX(-0.5,MIN(0.9,IFERROR('Hist_Financials'!D8/'Hist_Financials'!D6,0)+'Scenario_Library'!F8/10000))))-(MAX(0,'Hist_Financials'!D9*(1+'Scenario_Setup'!B9*('Scenario_Library'!E8)+('Scenario_Library'!G8))))-(MAX(0,'Hist_Financials'!D10*(1+'Scenario_Library'!H8))))-'Hist_Financials'!D12)-((MAX(0,IFERROR('Hist_Financials'!D14/MAX('Hist_Financials'!D27+'Hist_Financials'!D30,1),0)+'Scenario_Library'!L8/10000))*('Hist_Financials'!D27+'Hist_Financials'!D30))-('Hist_Financials'!D24*'Scenario_Library'!S8)-('Hist_Financials'!D25*'Scenario_Library'!T8)-('Hist_Financials'!D6*'Scenario_Library'!U8))-(MAX(0,((((('Hist_Financials'!D6*(1+'Scenario_Library'!E8))*(MAX(-0.5,MIN(0.9,IFERROR('Hist_Financials'!D8/'Hist_Financials'!D6,0)+'Scenario_Library'!F8/10000))))-(MAX(0,'Hist_Financials'!D9*(1+'Scenario_Setup'!B9*('Scenario_Library'!E8)+('Scenario_Library'!G8))))-(MAX(0,'Hist_Financials'!D10*(1+'Scenario_Library'!H8))))-'Hist_Financials'!D12)-((MAX(0,IFERROR('Hist_Financials'!D14/MAX('Hist_Financials'!D27+'Hist_Financials'!D30,1),0)+'Scenario_Library'!L8/10000))*('Hist_Financials'!D27+'Hist_Financials'!D30))-('Hist_Financials'!D24*'Scenario_Library'!S8)-('Hist_Financials'!D25*'Scenario_Library'!T8)-('Hist_Financials'!D6*'Scenario_Library'!U8)))*'Scenario_Library'!V8) | J5: =((((((('Hist_Financials'!D6*(1+'Scenario_Library'!E8))*(MAX(-0.5,MIN(0.9,IFERROR('Hist_Financials'!D8/'Hist_Financials'!D6,0)+'Scenario_Library'!F8/10000))))-(MAX(0,'Hist_Financials'!D9*(1+'Scenario_Setup'!B9*('Scenario_Library'!E8)+('Scenario_Library'!G8))))-(MAX(0,'Hist_Financials'!D10*(1+'Scenario_Library'!H8))))-'Hist_Financials'!D12)-((MAX(0,IFERROR('Hist_Financials'!D14/MAX('Hist_Financials'!D27+'Hist_Financials'!D30,1),0)+'Scenario_Library'!L8/10000))*('Hist_Financials'!D27+'Hist_Financials'!D30))-('Hist_Financials'!D24*'Scenario_Library'!S8)-('Hist_Financials'!D25*'Scenario_Library'!T8)-('Hist_Financials'!D6*'Scenario_Library'!U8))-(MAX(0,((((('Hist_Financials'!D6*(1+'Scenario_Library'!E8))*(MAX(-0.5,MIN(0.9,IFERROR('Hist_Financials'!D8/'Hist_Financials'!D6,0)+'Scenario_Library'!F8/10000))))-(MAX(0,'Hist_Financials'!D9*(1+'Scenario_Setup'!B9*('Scenario_Library'!E8)+('Scenario_Library'!G8))))-(MAX(0,'Hist_Financials'!D10*(1+'Scenario_Library'!H8))))-'Hist_Financials'!D12)-((MAX(0,IFERROR('Hist_Financials'!D14/MAX('Hist_Financials'!D27+'Hist_Financials'!D30,1),0)+'Scenario_Library'!L8/10000))*('Hist_Financials'!D27+'Hist_Financials'!D30))-('Hist_Financials'!D24*'Scenario_Library'!S8)-('Hist_Financials'!D25*'Scenario_Library'!T8)-('Hist_Financials'!D6*'Scenario_Library'!U8)))*'Scenario_Library'!V8))+'Hist_Financials'!D12+('Hist_Financials'!D24*'Scenario_Library'!S8)+('Hist_Financials'!D25*'Scenario_Library'!T8)-( (('Hist_Financials'!D6*(1+'Scenario_Library'!E8))*(MAX(0,IFERROR('Hist_Financials'!D21/'Hist_Financials'!D6*365,0)+'Scenario_Library'!I8))/365)-'Hist_Financials'!D21 )-( (IFERROR(('Hist_Financials'!D6*(1+'Scenario_Library'!E8))*(1-(MAX(-0.5,MIN(0.9,IFERROR('Hist_Financials'!D8/'Hist_Financials'!D6,0)+'Scenario_Library'!F8/10000))))*(MAX(0,IFERROR('Hist_Financials'!D22/'Hist_Financials'!D7*365,0)+'Scenario_Library'!J8))/365,0))-'Hist_Financials'!D22 )+( (IFERROR(('Hist_Financials'!D6*(1+'Scenario_Library'!E8))*(1-(MAX(-0.5,MIN(0.9,IFERROR('Hist_Financials'!D8/'Hist_Financials'!D6,0)+'Scenario_Library'!F8/10000))))*(MAX(0,IFERROR('Hist_Financials'!D28/'Hist_Financials'!D7*365,0)+'Scenario_Library'!K8))/365,0))-'Hist_Financials'!D28 ))-('Hist_Financials'!D36*(1-'Scenario_Library'!P8)) | K5: =MAX(0,'Hist_Financials'!D20+((((((('Hist_Financials'!D6*(1+'Scenario_Library'!E8))*(MAX(-0.5,MIN(0.9,IFERROR('Hist_Financials'!D8/'Hist_Financials'!D6,0)+'Scenario_Library'!F8/10000))))-(MAX(0,'Hist_Financials'!D9*(1+'Scenario_Setup'!B9*('Scenario_Library'!E8)+('Scenario_Library'!G8))))-(MAX(0,'Hist_Financials'!D10*(1+'Scenario_Library'!H8))))-'Hist_Financials'!D12)-((MAX(0,IFERROR('Hist_Financials'!D14/MAX('Hist_Financials'!D27+'Hist_Financials'!D30,1),0)+'Scenario_Library'!L8/10000))*('Hist_Financials'!D27+'Hist_Financials'!D30))-('Hist_Financials'!D24*'Scenario_Library'!S8)-('Hist_Financials'!D25*'Scenario_Library'!T8)-('Hist_Financials'!D6*'Scenario_Library'!U8))-(MAX(0,((((('Hist_Financials'!D6*(1+'Scenario_Library'!E8))*(MAX(-0.5,MIN(0.9,IFERROR('Hist_Financials'!D8/'Hist_Financials'!D6,0)+'Scenario_Library'!F8/10000))))-(MAX(0,'Hist_Financials'!D9*(1+'Scenario_Setup'!B9*('Scenario_Library'!E8)+('Scenario_Library'!G8))))-(MAX(0,'Hist_Financials'!D10*(1+'Scenario_Library'!H8))))-'Hist_Financials'!D12)-((MAX(0,IFERROR('Hist_Financials'!D14/MAX('Hist_Financials'!D27+'Hist_Financials'!D30,1),0)+'Scenario_Library'!L8/10000))*('Hist_Financials'!D27+'Hist_Financials'!D30))-('Hist_Financials'!D24*'Scenario_Library'!S8)-('Hist_Financials'!D25*'Scenario_Library'!T8)-('Hist_Financials'!D6*'Scenario_Library'!U8)))*'Scenario_Library'!V8))+'Hist_Financials'!D12+('Hist_Financials'!D24*'Scenario_Library'!S8)+('Hist_Financials'!D25*'Scenario_Library'!T8)-( (('Hist_Financials'!D6*(1+'Scenario_Library'!E8))*(MAX(0,IFERROR('Hist_Financials'!D21/'Hist_Financials'!D6*365,0)+'Scenario_Library'!I8))/365)-'Hist_Financials'!D21 )-( (IFERROR(('Hist_Financials'!D6*(1+'Scenario_Library'!E8))*(1-(MAX(-0.5,MIN(0.9,IFERROR('Hist_Financials'!D8/'Hist_Financials'!D6,0)+'Scenario_Library'!F8/10000))))*(MAX(0,IFERROR('Hist_Financials'!D22/'Hist_Financials'!D7*365,0)+'Scenario_Library'!J8))/365,0))-'Hist_Financials'!D22 )+( (IFERROR(('Hist_Financials'!D6*(1+'Scenario_Library'!E8))*(1-(MAX(-0.5,MIN(0.9,IFERROR('Hist_Financials'!D8/'Hist_Financials'!D6,0)+'Scenario_Library'!F8/10000))))*(MAX(0,IFERROR('Hist_Financials'!D28/'Hist_Financials'!D7*365,0)+'Scenario_Library'!K8))/365,0))-'Hist_Financials'!D28 ))-('Hist_Financials'!D36*(1-'Scenario_Library'!P8))-('Hist_Financials'!D37*(1-'Scenario_Library'!Q8))-('Hist_Financials'!D38*(1-'Scenario_Library'!R8))-('Hist_Financials'!D27*(1-'Scenario_Library'!M8))-('Hist_Financials'!D30*'Scenario_Library'!N8*(1-'Scenario_Library'!O8))) | L5: =IF('Hist_Financials'!D6=0,"",IFERROR(( (('Hist_Financials'!D27-('Hist_Financials'!D27*(1-'Scenario_Library'!M8)))+('Hist_Financials'!D30-('Hist_Financials'!D30*'Scenario_Library'!N8*(1-'Scenario_Library'!O8))))-(MAX(0,'Hist_Financials'!D20+((((((('Hist_Financials'!D6*(1+'Scenario_Library'!E8))*(MAX(-0.5,MIN(0.9,IFERROR('Hist_Financials'!D8/'Hist_Financials'!D6,0)+'Scenario_Library'!F8/10000))))-(MAX(0,'Hist_Financials'!D9*(1+'Scenario_Setup'!B9*('Scenario_Library'!E8)+('Scenario_Library'!G8))))-(MAX(0,'Hist_Financials'!D10*(1+'Scenario_Library'!H8))))-'Hist_Financials'!D12)-((MAX(0,IFERROR('Hist_Financials'!D14/MAX('Hist_Financials'!D27+'Hist_Financials'!D30,1),0)+'Scenario_Library'!L8/10000))*('Hist_Financials'!D27+'Hist_Financials'!D30))-('Hist_Financials'!D24*'Scenario_Library'!S8)-('Hist_Financials'!D25*'Scenario_Library'!T8)-('Hist_Financials'!D6*'Scenario_Library'!U8))-(MAX(0,((((('Hist_Financials'!D6*(1+'Scenario_Library'!E8))*(MAX(-0.5,MIN(0.9,IFERROR('Hist_Financials'!D8/'Hist_Financials'!D6,0)+'Scenario_Library'!F8/10000))))-(MAX(0,'Hist_Financials'!D9*(1+'Scenario_Setup'!B9*('Scenario_Library'!E8)+('Scenario_Library'!G8))))-(MAX(0,'Hist_Financials'!D10*(1+'Scenario_Library'!H8))))-'Hist_Financials'!D12)-((MAX(0,IFERROR('Hist_Financials'!D14/MAX('Hist_Financials'!D27+'Hist_Financials'!D30,1),0)+'Scenario_Library'!L8/10000))*('Hist_Financials'!D27+'Hist_Financials'!D30))-('Hist_Financials'!D24*'Scenario_Library'!S8)-('Hist_Financials'!D25*'Scenario_Library'!T8)-('Hist_Financials'!D6*'Scenario_Library'!U8)))*'Scenario_Library'!V8))+'Hist_Financials'!D12+('Hist_Financials'!D24*'Scenario_Library'!S8)+('Hist_Financials'!D25*'Scenario_Library'!T8)-( (('Hist_Financials'!D6*(1+'Scenario_Library'!E8))*(MAX(0,IFERROR('Hist_Financials'!D21/'Hist_Financials'!D6*365,0)+'Scenario_Library'!I8))/365)-'Hist_Financials'!D21 )-( (IFERROR(('Hist_Financials'!D6*(1+'Scenario_Library'!E8))*(1-(MAX(-0.5,MIN(0.9,IFERROR('Hist_Financials'!D8/'Hist_Financials'!D6,0)+'Scenario_Library'!F8/10000))))*(MAX(0,IFERROR('Hist_Financials'!D22/'Hist_Financials'!D7*365,0)+'Scenario_Library'!J8))/365,0))-'Hist_Financials'!D22 )+( (IFERROR(('Hist_Financials'!D6*(1+'Scenario_Library'!E8))*(1-(MAX(-0.5,MIN(0.9,IFERROR('Hist_Financials'!D8/'Hist_Financials'!D6,0)+'Scenario_Library'!F8/10000))))*(MAX(0,IFERROR('Hist_Financials'!D28/'Hist_Financials'!D7*365,0)+'Scenario_Library'!K8))/365,0))-'Hist_Financials'!D28 ))-('Hist_Financials'!D36*(1-'Scenario_Library'!P8))-('Hist_Financials'!D37*(1-'Scenario_Library'!Q8))-('Hist_Financials'!D38*(1-'Scenario_Library'!R8))-('Hist_Financials'!D27*(1-'Scenario_Library'!M8))-('Hist_Financials'!D30*'Scenario_Library'!N8*(1-'Scenario_Library'!O8)))) )/MAX(((('Hist_Financials'!D6*(1+'Scenario_Library'!E8))*(MAX(-0.5,MIN(0.9,IFERROR('Hist_Financials'!D8/'Hist_Financials'!D6,0)+'Scenario_Library'!F8/10000))))-(MAX(0,'Hist_Financials'!D9*(1+'Scenario_Setup'!B9*('Scenario_Library'!E8)+('Scenario_Library'!G8))))-(MAX(0,'Hist_Financials'!D10*(1+'Scenario_Library'!H8)))),0.01),99)) | M5: =IF('Hist_Financials'!D6=0,"",IFERROR((((('Hist_Financials'!D6*(1+'Scenario_Library'!E8))*(MAX(-0.5,MIN(0.9,IFERROR('Hist_Financials'!D8/'Hist_Financials'!D6,0)+'Scenario_Library'!F8/10000))))-(MAX(0,'Hist_Financials'!D9*(1+'Scenario_Setup'!B9*('Scenario_Library'!E8)+('Scenario_Library'!G8))))-(MAX(0,'Hist_Financials'!D10*(1+'Scenario_Library'!H8))))-'Hist_Financials'!D12)/MAX(((MAX(0,IFERROR('Hist_Financials'!D14/MAX('Hist_Financials'!D27+'Hist_Financials'!D30,1),0)+'Scenario_Library'!L8/10000))*('Hist_Financials'!D27+'Hist_Financials'!D30)),0.01),999)) | N5: =IF('Hist_Financials'!D6=0,"— NO DATA —",IF(OR((IFERROR(( (('Hist_Financials'!D27-('Hist_Financials'!D27*(1-'Scenario_Library'!M8)))+('Hist_Financials'!D30-('Hist_Financials'!D30*'Scenario_Library'!N8*(1-'Scenario_Library'!O8))))-(MAX(0,'Hist_Financials'!D20+((((((('Hist_Financials'!D6*(1+'Scenario_Library'!E8))*(MAX(-0.5,MIN(0.9,IFERROR('Hist_Financials'!D8/'Hist_Financials'!D6,0)+'Scenario_Library'!F8/10000))))-(MAX(0,'Hist_Financials'!D9*(1+'Scenario_Setup'!B9*('Scenario_Library'!E8)+('Scenario_Library'!G8))))-(MAX(0,'Hist_Financials'!D10*(1+'Scenario_Library'!H8))))-'Hist_Financials'!D12)-((MAX(0,IFERROR('Hist_Financials'!D14/MAX('Hist_Financials'!D27+'Hist_Financials'!D30,1),0)+'Scenario_Library'!L8/10000))*('Hist_Financials'!D27+'Hist_Financials'!D30))-('Hist_Financials'!D24*'Scenario_Library'!S8)-('Hist_Financials'!D25*'Scenario_Library'!T8)-('Hist_Financials'!D6*'Scenario_Library'!U8))-(MAX(0,((((('Hist_Financials'!D6*(1+'Scenario_Library'!E8))*(MAX(-0.5,MIN(0.9,IFERROR('Hist_Financials'!D8/'Hist_Financials'!D6,0)+'Scenario_Library'!F8/10000))))-(MAX(0,'Hist_Financials'!D9*(1+'Scenario_Setup'!B9*('Scenario_Library'!E8)+('Scenario_Library'!G8))))-(MAX(0,'Hist_Financials'!D10*(1+'Scenario_Library'!H8))))-'Hist_Financials'!D12)-((MAX(0,IFERROR('Hist_Financials'!D14/MAX('Hist_Financials'!D27+'Hist_Financials'!D30,1),0)+'Scenario_Library'!L8/10000))*('Hist_Financials'!D27+'Hist_Financials'!D30))-('Hist_Financials'!D24*'Scenario_Library'!S8)-('Hist_Financials'!D25*'Scenario_Library'!T8)-('Hist_Financials'!D6*'Scenario_Library'!U8)))*'Scenario_Library'!V8))+'Hist_Financials'!D12+('Hist_Financials'!D24*'Scenario_Library'!S8)+('Hist_Financials'!D25*'Scenario_Library'!T8)-( (('Hist_Financials'!D6*(1+'Scenario_Library'!E8))*(MAX(0,IFERROR('Hist_Financials'!D21/'Hist_Financials'!D6*365,0)+'Scenario_Library'!I8))/365)-'Hist_Financials'!D21 )-( (IFERROR(('Hist_Financials'!D6*(1+'Scenario_Library'!E8))*(1-(MAX(-0.5,MIN(0.9,IFERROR('Hist_Financials'!D8/'Hist_Financials'!D6,0)+'Scenario_Library'!F8/10000))))*(MAX(0,IFERROR('Hist_Financials'!D22/'Hist_Financials'!D7*365,0)+'Scenario_Library'!J8))/365,0))-'Hist_Financials'!D22 )+( (IFERROR(('Hist_Financials'!D6*(1+'Scenario_Library'!E8))*(1-(MAX(-0.5,MIN(0.9,IFERROR('Hist_Financials'!D8/'Hist_Financials'!D6,0)+'Scenario_Library'!F8/10000))))*(MAX(0,IFERROR('Hist_Financials'!D28/'Hist_Financials'!D7*365,0)+'Scenario_Library'!K8))/365,0))-'Hist_Financials'!D28 ))-('Hist_Financials'!D36*(1-'Scenario_Library'!P8))-('Hist_Financials'!D37*(1-'Scenario_Library'!Q8))-('Hist_Financials'!D38*(1-'Scenario_Library'!R8))-('Hist_Financials'!D27*(1-'Scenario_Library'!M8))-('Hist_Financials'!D30*'Scenario_Library'!N8*(1-'Scenario_Library'!O8)))) )/MAX(((('Hist_Financials'!D6*(1+'Scenario_Library'!E8))*(MAX(-0.5,MIN(0.9,IFERROR('Hist_Financials'!D8/'Hist_Financials'!D6,0)+'Scenario_Library'!F8/10000))))-(MAX(0,'Hist_Financials'!D9*(1+'Scenario_Setup'!B9*('Scenario_Library'!E8)+('Scenario_Library'!G8))))-(MAX(0,'Hist_Financials'!D10*(1+'Scenario_Library'!H8)))),0.01),99))>'Scenario_Setup'!B13,(IFERROR((((('Hist_Financials'!D6*(1+'Scenario_Library'!E8))*(MAX(-0.5,MIN(0.9,IFERROR('Hist_Financials'!D8/'Hist_Financials'!D6,0)+'Scenario_Library'!F8/10000))))-(MAX(0,'Hist_Financials'!D9*(1+'Scenario_Setup'!B9*('Scenario_Library'!E8)+('Scenario_Library'!G8))))-(MAX(0,'Hist_Financials'!D10*(1+'Scenario_Library'!H8))))-'Hist_Financials'!D12)/MAX(((MAX(0,IFERROR('Hist_Financials'!D14/MAX('Hist_Financials'!D27+'Hist_Financials'!D30,1),0)+'Scenario_Library'!L8/10000))*('Hist_Financials'!D27+'Hist_Financials'!D30)),0.01),999))<'Scenario_Setup'!B12,('Hist_Financials'!D32+(((((('Hist_Financials'!D6*(1+'Scenario_Library'!E8))*(MAX(-0.5,MIN(0.9,IFERROR('Hist_Financials'!D8/'Hist_Financials'!D6,0)+'Scenario_Library'!F8/10000))))-(MAX(0,'Hist_Financials'!D9*(1+'Scenario_Setup'!B9*('Scenario_Library'!E8)+('Scenario_Library'!G8))))-(MAX(0,'Hist_Financials'!D10*(1+'Scenario_Library'!H8))))-'Hist_Financials'!D12)-((MAX(0,IFERROR('Hist_Financials'!D14/MAX('Hist_Financials'!D27+'Hist_Financials'!D30,1),0)+'Scenario_Library'!L8/10000))*('Hist_Financials'!D27+'Hist_Financials'!D30))-('Hist_Financials'!D24*'Scenario_Library'!S8)-('Hist_Financials'!D25*'Scenario_Library'!T8)-('Hist_Financials'!D6*'Scenario_Library'!U8))-(MAX(0,((((('Hist_Financials'!D6*(1+'Scenario_Library'!E8))*(MAX(-0.5,MIN(0.9,IFERROR('Hist_Financials'!D8/'Hist_Financials'!D6,0)+'Scenario_Library'!F8/10000))))-(MAX(0,'Hist_Financials'!D9*(1+'Scenario_Setup'!B9*('Scenario_Library'!E8)+('Scenario_Library'!G8))))-(MAX(0,'Hist_Financials'!D10*(1+'Scenario_Library'!H8))))-'Hist_Financials'!D12)-((MAX(0,IFERROR('Hist_Financials'!D14/MAX('Hist_Financials'!D27+'Hist_Financials'!D30,1),0)+'Scenario_Library'!L8/10000))*('Hist_Financials'!D27+'Hist_Financials'!D30))-('Hist_Financials'!D24*'Scenario_Library'!S8)-('Hist_Financials'!D25*'Scenario_Library'!T8)-('Hist_Financials'!D6*'Scenario_Library'!U8)))*'Scenario_Library'!V8))-('Hist_Financials'!D37*(1-'Scenario_Library'!Q8))-('Hist_Financials'!D38*(1-'Scenario_Library'!R8)))<0,(((((((('Hist_Financials'!D6*(1+'Scenario_Library'!E8))*(MAX(-0.5,MIN(0.9,IFERROR('Hist_Financials'!D8/'Hist_Financials'!D6,0)+'Scenario_Library'!F8/10000))))-(MAX(0,'Hist_Financials'!D9*(1+'Scenario_Setup'!B9*('Scenario_Library'!E8)+('Scenario_Library'!G8))))-(MAX(0,'Hist_Financials'!D10*(1+'Scenario_Library'!H8))))-'Hist_Financials'!D12)-((MAX(0,IFERROR('Hist_Financials'!D14/MAX('Hist_Financials'!D27+'Hist_Financials'!D30,1),0)+'Scenario_Library'!L8/10000))*('Hist_Financials'!D27+'Hist_Financials'!D30))-('Hist_Financials'!D24*'Scenario_Library'!S8)-('Hist_Financials'!D25*'Scenario_Library'!T8)-('Hist_Financials'!D6*'Scenario_Library'!U8))-(MAX(0,((((('Hist_Financials'!D6*(1+'Scenario_Library'!E8))*(MAX(-0.5,MIN(0.9,IFERROR('Hist_Financials'!D8/'Hist_Financials'!D6,0)+'Scenario_Library'!F8/10000))))-(MAX(0,'Hist_Financials'!D9*(1+'Scenario_Setup'!B9*('Scenario_Library'!E8)+('Scenario_Library'!G8))))-(MAX(0,'Hist_Financials'!D10*(1+'Scenario_Library'!H8))))-'Hist_Financials'!D12)-((MAX(0,IFERROR('Hist_Financials'!D14/MAX('Hist_Financials'!D27+'Hist_Financials'!D30,1),0)+'Scenario_Library'!L8/10000))*('Hist_Financials'!D27+'Hist_Financials'!D30))-('Hist_Financials'!D24*'Scenario_Library'!S8)-('Hist_Financials'!D25*'Scenario_Library'!T8)-('Hist_Financials'!D6*'Scenario_Library'!U8)))*'Scenario_Library'!V8))+'Hist_Financials'!D12+('Hist_Financials'!D24*'Scenario_Library'!S8)+('Hist_Financials'!D25*'Scenario_Library'!T8)-( (('Hist_Financials'!D6*(1+'Scenario_Library'!E8))*(MAX(0,IFERROR('Hist_Financials'!D21/'Hist_Financials'!D6*365,0)+'Scenario_Library'!I8))/365)-'Hist_Financials'!D21 )-( (IFERROR(('Hist_Financials'!D6*(1+'Scenario_Library'!E8))*(1-(MAX(-0.5,MIN(0.9,IFERROR('Hist_Financials'!D8/'Hist_Financials'!D6,0)+'Scenario_Library'!F8/10000))))*(MAX(0,IFERROR('Hist_Financials'!D22/'Hist_Financials'!D7*365,0)+'Scenario_Library'!J8))/365,0))-'Hist_Financials'!D22 )+( (IFERROR(('Hist_Financials'!D6*(1+'Scenario_Library'!E8))*(1-(MAX(-0.5,MIN(0.9,IFERROR('Hist_Financials'!D8/'Hist_Financials'!D6,0)+'Scenario_Library'!F8/10000))))*(MAX(0,IFERROR('Hist_Financials'!D28/'Hist_Financials'!D7*365,0)+'Scenario_Library'!K8))/365,0))-'Hist_Financials'!D28 ))-('Hist_Financials'!D36*(1-'Scenario_Library'!P8)))<-0.2*'Hist_Financials'!D6),"CRITICAL",IF(AND((((((((('Hist_Financials'!D6*(1+'Scenario_Library'!E8))*(MAX(-0.5,MIN(0.9,IFERROR('Hist_Financials'!D8/'Hist_Financials'!D6,0)+'Scenario_Library'!F8/10000))))-(MAX(0,'Hist_Financials'!D9*(1+'Scenario_Setup'!B9*('Scenario_Library'!E8)+('Scenario_Library'!G8))))-(MAX(0,'Hist_Financials'!D10*(1+'Scenario_Library'!H8))))-'Hist_Financials'!D12)-((MAX(0,IFERROR('Hist_Financials'!D14/MAX('Hist_Financials'!D27+'Hist_Financials'!D30,1),0)+'Scenario_Library'!L8/10000))*('Hist_Financials'!D27+'Hist_Financials'!D30))-('Hist_Financials'!D24*'Scenario_Library'!S8)-('Hist_Financials'!D25*'Scenario_Library'!T8)-('Hist_Financials'!D6*'Scenario_Library'!U8))-(MAX(0,((((('Hist_Financials'!D6*(1+'Scenario_Library'!E8))*(MAX(-0.5,MIN(0.9,IFERROR('Hist_Financials'!D8/'Hist_Financials'!D6,0)+'Scenario_Library'!F8/10000))))-(MAX(0,'Hist_Financials'!D9*(1+'Scenario_Setup'!B9*('Scenario_Library'!E8)+('Scenario_Library'!G8))))-(MAX(0,'Hist_Financials'!D10*(1+'Scenario_Library'!H8))))-'Hist_Financials'!D12)-((MAX(0,IFERROR('Hist_Financials'!D14/MAX('Hist_Financials'!D27+'Hist_Financials'!D30,1),0)+'Scenario_Library'!L8/10000))*('Hist_Financials'!D27+'Hist_Financials'!D30))-('Hist_Financials'!D24*'Scenario_Library'!S8)-('Hist_Financials'!D25*'Scenario_Library'!T8)-('Hist_Financials'!D6*'Scenario_Library'!U8)))*'Scenario_Library'!V8))+'Hist_Financials'!D12+('Hist_Financials'!D24*'Scenario_Library'!S8)+('Hist_Financials'!D25*'Scenario_Library'!T8)-( (('Hist_Financials'!D6*(1+'Scenario_Library'!E8))*(MAX(0,IFERROR('Hist_Financials'!D21/'Hist_Financials'!D6*365,0)+'Scenario_Library'!I8))/365)-'Hist_Financials'!D21 )-( (IFERROR(('Hist_Financials'!D6*(1+'Scenario_Library'!E8))*(1-(MAX(-0.5,MIN(0.9,IFERROR('Hist_Financials'!D8/'Hist_Financials'!D6,0)+'Scenario_Library'!F8/10000))))*(MAX(0,IFERROR('Hist_Financials'!D22/'Hist_Financials'!D7*365,0)+'Scenario_Library'!J8))/365,0))-'Hist_Financials'!D22 )+( (IFERROR(('Hist_Financials'!D6*(1+'Scenario_Library'!E8))*(1-(MAX(-0.5,MIN(0.9,IFERROR('Hist_Financials'!D8/'Hist_Financials'!D6,0)+'Scenario_Library'!F8/10000))))*(MAX(0,IFERROR('Hist_Financials'!D28/'Hist_Financials'!D7*365,0)+'Scenario_Library'!K8))/365,0))-'Hist_Financials'!D28 ))-('Hist_Financials'!D36*(1-'Scenario_Library'!P8)))>=0,(IFERROR(( (('Hist_Financials'!D27-('Hist_Financials'!D27*(1-'Scenario_Library'!M8)))+('Hist_Financials'!D30-('Hist_Financials'!D30*'Scenario_Library'!N8*(1-'Scenario_Library'!O8))))-(MAX(0,'Hist_Financials'!D20+((((((('Hist_Financials'!D6*(1+'Scenario_Library'!E8))*(MAX(-0.5,MIN(0.9,IFERROR('Hist_Financials'!D8/'Hist_Financials'!D6,0)+'Scenario_Library'!F8/10000))))-(MAX(0,'Hist_Financials'!D9*(1+'Scenario_Setup'!B9*('Scenario_Library'!E8)+('Scenario_Library'!G8))))-(MAX(0,'Hist_Financials'!D10*(1+'Scenario_Library'!H8))))-'Hist_Financials'!D12)-((MAX(0,IFERROR('Hist_Financials'!D14/MAX('Hist_Financials'!D27+'Hist_Financials'!D30,1),0)+'Scenario_Library'!L8/10000))*('Hist_Financials'!D27+'Hist_Financials'!D30))-('Hist_Financials'!D24*'Scenario_Library'!S8)-('Hist_Financials'!D25*'Scenario_Library'!T8)-('Hist_Financials'!D6*'Scenario_Library'!U8))-(MAX(0,((((('Hist_Financials'!D6*(1+'Scenario_Library'!E8))*(MAX(-0.5,MIN(0.9,IFERROR('Hist_Financials'!D8/'Hist_Financials'!D6,0)+'Scenario_Library'!F8/10000))))-(MAX(0,'Hist_Financials'!D9*(1+'Scenario_Setup'!B9*('Scenario_Library'!E8)+('Scenario_Library'!G8))))-(MAX(0,'Hist_Financials'!D10*(1+'Scenario_Library'!H8))))-'Hist_Financials'!D12)-((MAX(0,IFERROR('Hist_Financials'!D14/MAX('Hist_Financials'!D27+'Hist_Financials'!D30,1),0)+'Scenario_Library'!L8/10000))*('Hist_Financials'!D27+'Hist_Financials'!D30))-('Hist_Financials'!D24*'Scenario_Library'!S8)-('Hist_Financials'!D25*'Scenario_Library'!T8)-('Hist_Financials'!D6*'Scenario_Library'!U8)))*'Scenario_Library'!V8))+'Hist_Financials'!D12+('Hist_Financials'!D24*'Scenario_Library'!S8)+('Hist_Financials'!D25*'Scenario_Library'!T8)-( (('Hist_Financials'!D6*(1+'Scenario_Library'!E8))*(MAX(0,IFERROR('Hist_Financials'!D21/'Hist_Financials'!D6*365,0)+'Scenario_Library'!I8))/365)-'Hist_Financials'!D21 )-( (IFERROR(('Hist_Financials'!D6*(1+'Scenario_Library'!E8))*(1-(MAX(-0.5,MIN(0.9,IFERROR('Hist_Financials'!D8/'Hist_Financials'!D6,0)+'Scenario_Library'!F8/10000))))*(MAX(0,IFERROR('Hist_Financials'!D22/'Hist_Financials'!D7*365,0)+'Scenario_Library'!J8))/365,0))-'Hist_Financials'!D22 )+( (IFERROR(('Hist_Financials'!D6*(1+'Scenario_Library'!E8))*(1-(MAX(-0.5,MIN(0.9,IFERROR('Hist_Financials'!D8/'Hist_Financials'!D6,0)+'Scenario_Library'!F8/10000))))*(MAX(0,IFERROR('Hist_Financials'!D28/'Hist_Financials'!D7*365,0)+'Scenario_Library'!K8))/365,0))-'Hist_Financials'!D28 ))-('Hist_Financials'!D36*(1-'Scenario_Library'!P8))-('Hist_Financials'!D37*(1-'Scenario_Library'!Q8))-('Hist_Financials'!D38*(1-'Scenario_Library'!R8))-('Hist_Financials'!D27*(1-'Scenario_Library'!M8))-('Hist_Financials'!D30*'Scenario_Library'!N8*(1-'Scenario_Library'!O8)))) )/MAX(((('Hist_Financials'!D6*(1+'Scenario_Library'!E8))*(MAX(-0.5,MIN(0.9,IFERROR('Hist_Financials'!D8/'Hist_Financials'!D6,0)+'Scenario_Library'!F8/10000))))-(MAX(0,'Hist_Financials'!D9*(1+'Scenario_Setup'!B9*('Scenario_Library'!E8)+('Scenario_Library'!G8))))-(MAX(0,'Hist_Financials'!D10*(1+'Scenario_Library'!H8)))),0.01),99))<3,(IFERROR((((('Hist_Financials'!D6*(1+'Scenario_Library'!E8))*(MAX(-0.5,MIN(0.9,IFERROR('Hist_Financials'!D8/'Hist_Financials'!D6,0)+'Scenario_Library'!F8/10000))))-(MAX(0,'Hist_Financials'!D9*(1+'Scenario_Setup'!B9*('Scenario_Library'!E8)+('Scenario_Library'!G8))))-(MAX(0,'Hist_Financials'!D10*(1+'Scenario_Library'!H8))))-'Hist_Financials'!D12)/MAX(((MAX(0,IFERROR('Hist_Financials'!D14/MAX('Hist_Financials'!D27+'Hist_Financials'!D30,1),0)+'Scenario_Library'!L8/10000))*('Hist_Financials'!D27+'Hist_Financials'!D30)),0.01),999))>='Scenario_Setup'!B12,('Hist_Financials'!D32+(((((('Hist_Financials'!D6*(1+'Scenario_Library'!E8))*(MAX(-0.5,MIN(0.9,IFERROR('Hist_Financials'!D8/'Hist_Financials'!D6,0)+'Scenario_Library'!F8/10000))))-(MAX(0,'Hist_Financials'!D9*(1+'Scenario_Setup'!B9*('Scenario_Library'!E8)+('Scenario_Library'!G8))))-(MAX(0,'Hist_Financials'!D10*(1+'Scenario_Library'!H8))))-'Hist_Financials'!D12)-((MAX(0,IFERROR('Hist_Financials'!D14/MAX('Hist_Financials'!D27+'Hist_Financials'!D30,1),0)+'Scenario_Library'!L8/10000))*('Hist_Financials'!D27+'Hist_Financials'!D30))-('Hist_Financials'!D24*'Scenario_Library'!S8)-('Hist_Financials'!D25*'Scenario_Library'!T8)-('Hist_Financials'!D6*'Scenario_Library'!U8))-(MAX(0,((((('Hist_Financials'!D6*(1+'Scenario_Library'!E8))*(MAX(-0.5,MIN(0.9,IFERROR('Hist_Financials'!D8/'Hist_Financials'!D6,0)+'Scenario_Library'!F8/10000))))-(MAX(0,'Hist_Financials'!D9*(1+'Scenario_Setup'!B9*('Scenario_Library'!E8)+('Scenario_Library'!G8))))-(MAX(0,'Hist_Financials'!D10*(1+'Scenario_Library'!H8))))-'Hist_Financials'!D12)-((MAX(0,IFERROR('Hist_Financials'!D14/MAX('Hist_Financials'!D27+'Hist_Financials'!D30,1),0)+'Scenario_Library'!L8/10000))*('Hist_Financials'!D27+'Hist_Financials'!D30))-('Hist_Financials'!D24*'Scenario_Library'!S8)-('Hist_Financials'!D25*'Scenario_Library'!T8)-('Hist_Financials'!D6*'Scenario_Library'!U8)))*'Scenario_Library'!V8))-('Hist_Financials'!D37*(1-'Scenario_Library'!Q8))-('Hist_Financials'!D38*(1-'Scenario_Library'!R8)))>0),"RESILIENT","WATCH")))
